[2025-01-01T23:26:08.161+0000] {local_task_job_runner.py:123} INFO - ::group::Pre task execution logs
[2025-01-01T23:26:08.205+0000] {taskinstance.py:2613} INFO - Dependencies all met for dep_context=non-requeueable deps ti=<TaskInstance: create_table_dag.create_tables manual__2025-01-01T23:26:05.724443+00:00 [queued]>
[2025-01-01T23:26:08.224+0000] {taskinstance.py:2613} INFO - Dependencies all met for dep_context=requeueable deps ti=<TaskInstance: create_table_dag.create_tables manual__2025-01-01T23:26:05.724443+00:00 [queued]>
[2025-01-01T23:26:08.225+0000] {taskinstance.py:2866} INFO - Starting attempt 1 of 3
[2025-01-01T23:26:08.255+0000] {taskinstance.py:2889} INFO - Executing <Task(PythonOperator): create_tables> on 2025-01-01 23:26:05.724443+00:00
[2025-01-01T23:26:08.268+0000] {warnings.py:112} WARNING - /home/***/.local/lib/python3.12/site-packages/***/task/task_runner/standard_task_runner.py:70: DeprecationWarning: This process (pid=10370) is multi-threaded, use of fork() may lead to deadlocks in the child.
  pid = os.fork()

[2025-01-01T23:26:08.270+0000] {standard_task_runner.py:72} INFO - Started process 10371 to run task
[2025-01-01T23:26:08.271+0000] {standard_task_runner.py:104} INFO - Running: ['***', 'tasks', 'run', 'create_table_dag', 'create_tables', 'manual__2025-01-01T23:26:05.724443+00:00', '--job-id', '32', '--raw', '--subdir', 'DAGS_FOLDER/create_table_dag.py', '--cfg-path', '/tmp/tmpzar3rck7']
[2025-01-01T23:26:08.273+0000] {standard_task_runner.py:105} INFO - Job 32: Subtask create_tables
[2025-01-01T23:26:08.306+0000] {warnings.py:112} WARNING - /home/***/.local/lib/python3.12/site-packages/***/settings.py:209: DeprecationWarning: The sql_alchemy_conn option in [core] has been moved to the sql_alchemy_conn option in [database] - the old setting has been used, but please update your config.
  SQL_ALCHEMY_CONN = conf.get("database", "SQL_ALCHEMY_CONN")

[2025-01-01T23:26:08.380+0000] {task_command.py:467} INFO - Running <TaskInstance: create_table_dag.create_tables manual__2025-01-01T23:26:05.724443+00:00 [running]> on host 3c8b1d3a3cdf
[2025-01-01T23:26:08.515+0000] {taskinstance.py:3132} INFO - Exporting env vars: AIRFLOW_CTX_DAG_OWNER='aiflow' AIRFLOW_CTX_DAG_ID='create_table_dag' AIRFLOW_CTX_TASK_ID='create_tables' AIRFLOW_CTX_EXECUTION_DATE='2025-01-01T23:26:05.724443+00:00' AIRFLOW_CTX_TRY_NUMBER='1' AIRFLOW_CTX_DAG_RUN_ID='manual__2025-01-01T23:26:05.724443+00:00'
[2025-01-01T23:26:08.516+0000] {taskinstance.py:731} INFO - ::endgroup::
[2025-01-01T23:26:08.538+0000] {utils.py:62} ERROR - Error connecting to News sentiment analysis database: connection to server at "localhost" (::1), port 5432 failed: Connection refused
	Is the server running on that host and accepting TCP/IP connections?
connection to server at "localhost" (127.0.0.1), port 5432 failed: Connection refused
	Is the server running on that host and accepting TCP/IP connections?

[2025-01-01T23:26:08.538+0000] {create_table_dag.py:28} ERROR - Error creating tables: 'NoneType' object has no attribute 'autocommit'
[2025-01-01T23:26:08.539+0000] {taskinstance.py:3311} ERROR - Task failed with exception
Traceback (most recent call last):
  File "/opt/airflow/dags/create_table_dag.py", line 15, in create_tables
    connection.autocommit = True
    ^^^^^^^^^^^^^^^^^^^^^
AttributeError: 'NoneType' object has no attribute 'autocommit'

During handling of the above exception, another exception occurred:

Traceback (most recent call last):
  File "/home/airflow/.local/lib/python3.12/site-packages/airflow/models/taskinstance.py", line 767, in _execute_task
    result = _execute_callable(context=context, **execute_callable_kwargs)
             ^^^^^^^^^^^^^^^^^^^^^^^^^^^^^^^^^^^^^^^^^^^^^^^^^^^^^^^^^^^^^
  File "/home/airflow/.local/lib/python3.12/site-packages/airflow/models/taskinstance.py", line 733, in _execute_callable
    return ExecutionCallableRunner(
           ^^^^^^^^^^^^^^^^^^^^^^^^
  File "/home/airflow/.local/lib/python3.12/site-packages/airflow/utils/operator_helpers.py", line 252, in run
    return self.func(*args, **kwargs)
           ^^^^^^^^^^^^^^^^^^^^^^^^^^
  File "/home/airflow/.local/lib/python3.12/site-packages/airflow/models/baseoperator.py", line 422, in wrapper
    return func(self, *args, **kwargs)
           ^^^^^^^^^^^^^^^^^^^^^^^^^^^
  File "/home/airflow/.local/lib/python3.12/site-packages/airflow/operators/python.py", line 238, in execute
    return_value = self.execute_callable()
                   ^^^^^^^^^^^^^^^^^^^^^^^
  File "/home/airflow/.local/lib/python3.12/site-packages/airflow/operators/python.py", line 256, in execute_callable
    return runner.run(*self.op_args, **self.op_kwargs)
           ^^^^^^^^^^^^^^^^^^^^^^^^^^^^^^^^^^^^^^^^^^^
  File "/home/airflow/.local/lib/python3.12/site-packages/airflow/utils/operator_helpers.py", line 252, in run
    return self.func(*args, **kwargs)
           ^^^^^^^^^^^^^^^^^^^^^^^^^^
  File "/opt/airflow/dags/create_table_dag.py", line 31, in create_tables
    cursor.close()
    ^^^^^^
UnboundLocalError: cannot access local variable 'cursor' where it is not associated with a value
[2025-01-01T23:26:08.560+0000] {taskinstance.py:1225} INFO - Marking task as UP_FOR_RETRY. dag_id=create_table_dag, task_id=create_tables, run_id=manual__2025-01-01T23:26:05.724443+00:00, execution_date=20250101T232605, start_date=20250101T232608, end_date=20250101T232608
[2025-01-01T23:26:08.589+0000] {taskinstance.py:340} INFO - ::group::Post task execution logs
[2025-01-01T23:26:08.590+0000] {standard_task_runner.py:124} ERROR - Failed to execute job 32 for task create_tables (cannot access local variable 'cursor' where it is not associated with a value; 10371)
Traceback (most recent call last):
  File "/opt/airflow/dags/create_table_dag.py", line 15, in create_tables
    connection.autocommit = True
    ^^^^^^^^^^^^^^^^^^^^^
AttributeError: 'NoneType' object has no attribute 'autocommit'

During handling of the above exception, another exception occurred:

Traceback (most recent call last):
  File "/home/airflow/.local/lib/python3.12/site-packages/airflow/task/task_runner/standard_task_runner.py", line 117, in _start_by_fork
    ret = args.func(args, dag=self.dag)
          ^^^^^^^^^^^^^^^^^^^^^^^^^^^^^
  File "/home/airflow/.local/lib/python3.12/site-packages/airflow/cli/cli_config.py", line 49, in command
    return func(*args, **kwargs)
           ^^^^^^^^^^^^^^^^^^^^^
  File "/home/airflow/.local/lib/python3.12/site-packages/airflow/utils/cli.py", line 116, in wrapper
    return f(*args, **kwargs)
           ^^^^^^^^^^^^^^^^^^
  File "/home/airflow/.local/lib/python3.12/site-packages/airflow/cli/commands/task_command.py", line 483, in task_run
    task_return_code = _run_task_by_selected_method(args, _dag, ti)
                       ^^^^^^^^^^^^^^^^^^^^^^^^^^^^^^^^^^^^^^^^^^^^
  File "/home/airflow/.local/lib/python3.12/site-packages/airflow/cli/commands/task_command.py", line 256, in _run_task_by_selected_method
    return _run_raw_task(args, ti)
           ^^^^^^^^^^^^^^^^^^^^^^^
  File "/home/airflow/.local/lib/python3.12/site-packages/airflow/cli/commands/task_command.py", line 341, in _run_raw_task
    return ti._run_raw_task(
           ^^^^^^^^^^^^^^^^^
  File "/home/airflow/.local/lib/python3.12/site-packages/airflow/utils/session.py", line 97, in wrapper
    return func(*args, session=session, **kwargs)
           ^^^^^^^^^^^^^^^^^^^^^^^^^^^^^^^^^^^^^^
  File "/home/airflow/.local/lib/python3.12/site-packages/airflow/models/taskinstance.py", line 3005, in _run_raw_task
    return _run_raw_task(
           ^^^^^^^^^^^^^^
  File "/home/airflow/.local/lib/python3.12/site-packages/airflow/models/taskinstance.py", line 273, in _run_raw_task
    TaskInstance._execute_task_with_callbacks(
  File "/home/airflow/.local/lib/python3.12/site-packages/airflow/models/taskinstance.py", line 3159, in _execute_task_with_callbacks
    result = self._execute_task(context, task_orig)
             ^^^^^^^^^^^^^^^^^^^^^^^^^^^^^^^^^^^^^^
  File "/home/airflow/.local/lib/python3.12/site-packages/airflow/models/taskinstance.py", line 3183, in _execute_task
    return _execute_task(self, context, task_orig)
           ^^^^^^^^^^^^^^^^^^^^^^^^^^^^^^^^^^^^^^^
  File "/home/airflow/.local/lib/python3.12/site-packages/airflow/models/taskinstance.py", line 767, in _execute_task
    result = _execute_callable(context=context, **execute_callable_kwargs)
             ^^^^^^^^^^^^^^^^^^^^^^^^^^^^^^^^^^^^^^^^^^^^^^^^^^^^^^^^^^^^^
  File "/home/airflow/.local/lib/python3.12/site-packages/airflow/models/taskinstance.py", line 733, in _execute_callable
    return ExecutionCallableRunner(
           ^^^^^^^^^^^^^^^^^^^^^^^^
  File "/home/airflow/.local/lib/python3.12/site-packages/airflow/utils/operator_helpers.py", line 252, in run
    return self.func(*args, **kwargs)
           ^^^^^^^^^^^^^^^^^^^^^^^^^^
  File "/home/airflow/.local/lib/python3.12/site-packages/airflow/models/baseoperator.py", line 422, in wrapper
    return func(self, *args, **kwargs)
           ^^^^^^^^^^^^^^^^^^^^^^^^^^^
  File "/home/airflow/.local/lib/python3.12/site-packages/airflow/operators/python.py", line 238, in execute
    return_value = self.execute_callable()
                   ^^^^^^^^^^^^^^^^^^^^^^^
  File "/home/airflow/.local/lib/python3.12/site-packages/airflow/operators/python.py", line 256, in execute_callable
    return runner.run(*self.op_args, **self.op_kwargs)
           ^^^^^^^^^^^^^^^^^^^^^^^^^^^^^^^^^^^^^^^^^^^
  File "/home/airflow/.local/lib/python3.12/site-packages/airflow/utils/operator_helpers.py", line 252, in run
    return self.func(*args, **kwargs)
           ^^^^^^^^^^^^^^^^^^^^^^^^^^
  File "/opt/airflow/dags/create_table_dag.py", line 31, in create_tables
    cursor.close()
    ^^^^^^
UnboundLocalError: cannot access local variable 'cursor' where it is not associated with a value
[2025-01-01T23:26:08.609+0000] {local_task_job_runner.py:266} INFO - Task exited with return code 1
[2025-01-01T23:26:08.646+0000] {taskinstance.py:3895} INFO - 0 downstream tasks scheduled from follow-on schedule check
[2025-01-01T23:26:08.648+0000] {local_task_job_runner.py:245} INFO - ::endgroup::
