[2025-01-01T23:20:25.594+0000] {local_task_job_runner.py:123} INFO - ::group::Pre task execution logs
[2025-01-01T23:20:25.621+0000] {taskinstance.py:2613} INFO - Dependencies all met for dep_context=non-requeueable deps ti=<TaskInstance: create_table_dag.create_tables manual__2025-01-01T23:20:23.301638+00:00 [queued]>
[2025-01-01T23:20:25.635+0000] {taskinstance.py:2613} INFO - Dependencies all met for dep_context=requeueable deps ti=<TaskInstance: create_table_dag.create_tables manual__2025-01-01T23:20:23.301638+00:00 [queued]>
[2025-01-01T23:20:25.635+0000] {taskinstance.py:2866} INFO - Starting attempt 1 of 3
[2025-01-01T23:20:25.662+0000] {taskinstance.py:2889} INFO - Executing <Task(PythonOperator): create_tables> on 2025-01-01 23:20:23.301638+00:00
[2025-01-01T23:20:25.679+0000] {warnings.py:112} WARNING - /home/***/.local/lib/python3.12/site-packages/***/task/task_runner/standard_task_runner.py:70: DeprecationWarning: This process (pid=10189) is multi-threaded, use of fork() may lead to deadlocks in the child.
  pid = os.fork()

[2025-01-01T23:20:25.681+0000] {standard_task_runner.py:72} INFO - Started process 10190 to run task
[2025-01-01T23:20:25.683+0000] {standard_task_runner.py:104} INFO - Running: ['***', 'tasks', 'run', 'create_table_dag', 'create_tables', 'manual__2025-01-01T23:20:23.301638+00:00', '--job-id', '30', '--raw', '--subdir', 'DAGS_FOLDER/create_table_dag.py', '--cfg-path', '/tmp/tmpm5bnxb6_']
[2025-01-01T23:20:25.692+0000] {standard_task_runner.py:105} INFO - Job 30: Subtask create_tables
[2025-01-01T23:20:25.713+0000] {warnings.py:112} WARNING - /home/***/.local/lib/python3.12/site-packages/***/settings.py:209: DeprecationWarning: The sql_alchemy_conn option in [core] has been moved to the sql_alchemy_conn option in [database] - the old setting has been used, but please update your config.
  SQL_ALCHEMY_CONN = conf.get("database", "SQL_ALCHEMY_CONN")

[2025-01-01T23:20:25.777+0000] {task_command.py:467} INFO - Running <TaskInstance: create_table_dag.create_tables manual__2025-01-01T23:20:23.301638+00:00 [running]> on host 3c8b1d3a3cdf
[2025-01-01T23:20:25.894+0000] {taskinstance.py:3132} INFO - Exporting env vars: AIRFLOW_CTX_DAG_OWNER='aiflow' AIRFLOW_CTX_DAG_ID='create_table_dag' AIRFLOW_CTX_TASK_ID='create_tables' AIRFLOW_CTX_EXECUTION_DATE='2025-01-01T23:20:23.301638+00:00' AIRFLOW_CTX_TRY_NUMBER='1' AIRFLOW_CTX_DAG_RUN_ID='manual__2025-01-01T23:20:23.301638+00:00'
[2025-01-01T23:20:25.895+0000] {taskinstance.py:731} INFO - ::endgroup::
[2025-01-01T23:20:25.913+0000] {utils.py:50} ERROR - Error connecting to News sentiment analysis database: connection to server on socket "/var/run/postgresql/.s.PGSQL.5433" failed: No such file or directory
	Is the server running locally and accepting connections on that socket?

[2025-01-01T23:20:25.914+0000] {create_table_dag.py:28} ERROR - Error creating tables: 'NoneType' object has no attribute 'autocommit'
[2025-01-01T23:20:25.914+0000] {taskinstance.py:3311} ERROR - Task failed with exception
Traceback (most recent call last):
  File "/opt/airflow/dags/create_table_dag.py", line 15, in create_tables
    connection.autocommit = True
    ^^^^^^^^^^^^^^^^^^^^^
AttributeError: 'NoneType' object has no attribute 'autocommit'

During handling of the above exception, another exception occurred:

Traceback (most recent call last):
  File "/home/airflow/.local/lib/python3.12/site-packages/airflow/models/taskinstance.py", line 767, in _execute_task
    result = _execute_callable(context=context, **execute_callable_kwargs)
             ^^^^^^^^^^^^^^^^^^^^^^^^^^^^^^^^^^^^^^^^^^^^^^^^^^^^^^^^^^^^^
  File "/home/airflow/.local/lib/python3.12/site-packages/airflow/models/taskinstance.py", line 733, in _execute_callable
    return ExecutionCallableRunner(
           ^^^^^^^^^^^^^^^^^^^^^^^^
  File "/home/airflow/.local/lib/python3.12/site-packages/airflow/utils/operator_helpers.py", line 252, in run
    return self.func(*args, **kwargs)
           ^^^^^^^^^^^^^^^^^^^^^^^^^^
  File "/home/airflow/.local/lib/python3.12/site-packages/airflow/models/baseoperator.py", line 422, in wrapper
    return func(self, *args, **kwargs)
           ^^^^^^^^^^^^^^^^^^^^^^^^^^^
  File "/home/airflow/.local/lib/python3.12/site-packages/airflow/operators/python.py", line 238, in execute
    return_value = self.execute_callable()
                   ^^^^^^^^^^^^^^^^^^^^^^^
  File "/home/airflow/.local/lib/python3.12/site-packages/airflow/operators/python.py", line 256, in execute_callable
    return runner.run(*self.op_args, **self.op_kwargs)
           ^^^^^^^^^^^^^^^^^^^^^^^^^^^^^^^^^^^^^^^^^^^
  File "/home/airflow/.local/lib/python3.12/site-packages/airflow/utils/operator_helpers.py", line 252, in run
    return self.func(*args, **kwargs)
           ^^^^^^^^^^^^^^^^^^^^^^^^^^
  File "/opt/airflow/dags/create_table_dag.py", line 31, in create_tables
    cursor.close()
    ^^^^^^
UnboundLocalError: cannot access local variable 'cursor' where it is not associated with a value
[2025-01-01T23:20:25.934+0000] {taskinstance.py:1225} INFO - Marking task as UP_FOR_RETRY. dag_id=create_table_dag, task_id=create_tables, run_id=manual__2025-01-01T23:20:23.301638+00:00, execution_date=20250101T232023, start_date=20250101T232025, end_date=20250101T232025
[2025-01-01T23:20:25.955+0000] {taskinstance.py:340} INFO - ::group::Post task execution logs
[2025-01-01T23:20:25.956+0000] {standard_task_runner.py:124} ERROR - Failed to execute job 30 for task create_tables (cannot access local variable 'cursor' where it is not associated with a value; 10190)
Traceback (most recent call last):
  File "/opt/airflow/dags/create_table_dag.py", line 15, in create_tables
    connection.autocommit = True
    ^^^^^^^^^^^^^^^^^^^^^
AttributeError: 'NoneType' object has no attribute 'autocommit'

During handling of the above exception, another exception occurred:

Traceback (most recent call last):
  File "/home/airflow/.local/lib/python3.12/site-packages/airflow/task/task_runner/standard_task_runner.py", line 117, in _start_by_fork
    ret = args.func(args, dag=self.dag)
          ^^^^^^^^^^^^^^^^^^^^^^^^^^^^^
  File "/home/airflow/.local/lib/python3.12/site-packages/airflow/cli/cli_config.py", line 49, in command
    return func(*args, **kwargs)
           ^^^^^^^^^^^^^^^^^^^^^
  File "/home/airflow/.local/lib/python3.12/site-packages/airflow/utils/cli.py", line 116, in wrapper
    return f(*args, **kwargs)
           ^^^^^^^^^^^^^^^^^^
  File "/home/airflow/.local/lib/python3.12/site-packages/airflow/cli/commands/task_command.py", line 483, in task_run
    task_return_code = _run_task_by_selected_method(args, _dag, ti)
                       ^^^^^^^^^^^^^^^^^^^^^^^^^^^^^^^^^^^^^^^^^^^^
  File "/home/airflow/.local/lib/python3.12/site-packages/airflow/cli/commands/task_command.py", line 256, in _run_task_by_selected_method
    return _run_raw_task(args, ti)
           ^^^^^^^^^^^^^^^^^^^^^^^
  File "/home/airflow/.local/lib/python3.12/site-packages/airflow/cli/commands/task_command.py", line 341, in _run_raw_task
    return ti._run_raw_task(
           ^^^^^^^^^^^^^^^^^
  File "/home/airflow/.local/lib/python3.12/site-packages/airflow/utils/session.py", line 97, in wrapper
    return func(*args, session=session, **kwargs)
           ^^^^^^^^^^^^^^^^^^^^^^^^^^^^^^^^^^^^^^
  File "/home/airflow/.local/lib/python3.12/site-packages/airflow/models/taskinstance.py", line 3005, in _run_raw_task
    return _run_raw_task(
           ^^^^^^^^^^^^^^
  File "/home/airflow/.local/lib/python3.12/site-packages/airflow/models/taskinstance.py", line 273, in _run_raw_task
    TaskInstance._execute_task_with_callbacks(
  File "/home/airflow/.local/lib/python3.12/site-packages/airflow/models/taskinstance.py", line 3159, in _execute_task_with_callbacks
    result = self._execute_task(context, task_orig)
             ^^^^^^^^^^^^^^^^^^^^^^^^^^^^^^^^^^^^^^
  File "/home/airflow/.local/lib/python3.12/site-packages/airflow/models/taskinstance.py", line 3183, in _execute_task
    return _execute_task(self, context, task_orig)
           ^^^^^^^^^^^^^^^^^^^^^^^^^^^^^^^^^^^^^^^
  File "/home/airflow/.local/lib/python3.12/site-packages/airflow/models/taskinstance.py", line 767, in _execute_task
    result = _execute_callable(context=context, **execute_callable_kwargs)
             ^^^^^^^^^^^^^^^^^^^^^^^^^^^^^^^^^^^^^^^^^^^^^^^^^^^^^^^^^^^^^
  File "/home/airflow/.local/lib/python3.12/site-packages/airflow/models/taskinstance.py", line 733, in _execute_callable
    return ExecutionCallableRunner(
           ^^^^^^^^^^^^^^^^^^^^^^^^
  File "/home/airflow/.local/lib/python3.12/site-packages/airflow/utils/operator_helpers.py", line 252, in run
    return self.func(*args, **kwargs)
           ^^^^^^^^^^^^^^^^^^^^^^^^^^
  File "/home/airflow/.local/lib/python3.12/site-packages/airflow/models/baseoperator.py", line 422, in wrapper
    return func(self, *args, **kwargs)
           ^^^^^^^^^^^^^^^^^^^^^^^^^^^
  File "/home/airflow/.local/lib/python3.12/site-packages/airflow/operators/python.py", line 238, in execute
    return_value = self.execute_callable()
                   ^^^^^^^^^^^^^^^^^^^^^^^
  File "/home/airflow/.local/lib/python3.12/site-packages/airflow/operators/python.py", line 256, in execute_callable
    return runner.run(*self.op_args, **self.op_kwargs)
           ^^^^^^^^^^^^^^^^^^^^^^^^^^^^^^^^^^^^^^^^^^^
  File "/home/airflow/.local/lib/python3.12/site-packages/airflow/utils/operator_helpers.py", line 252, in run
    return self.func(*args, **kwargs)
           ^^^^^^^^^^^^^^^^^^^^^^^^^^
  File "/opt/airflow/dags/create_table_dag.py", line 31, in create_tables
    cursor.close()
    ^^^^^^
UnboundLocalError: cannot access local variable 'cursor' where it is not associated with a value
[2025-01-01T23:20:25.990+0000] {local_task_job_runner.py:266} INFO - Task exited with return code 1
[2025-01-01T23:20:26.021+0000] {taskinstance.py:3895} INFO - 0 downstream tasks scheduled from follow-on schedule check
[2025-01-01T23:20:26.024+0000] {local_task_job_runner.py:245} INFO - ::endgroup::
