[2025-01-02T01:50:03.758+0000] {local_task_job_runner.py:123} INFO - ::group::Pre task execution logs
[2025-01-02T01:50:03.781+0000] {taskinstance.py:2613} INFO - Dependencies all met for dep_context=non-requeueable deps ti=<TaskInstance: daily_news_dag.daily_news_etl_run scheduled__2025-01-02T01:40:00+00:00 [queued]>
[2025-01-02T01:50:03.793+0000] {taskinstance.py:2613} INFO - Dependencies all met for dep_context=requeueable deps ti=<TaskInstance: daily_news_dag.daily_news_etl_run scheduled__2025-01-02T01:40:00+00:00 [queued]>
[2025-01-02T01:50:03.794+0000] {taskinstance.py:2866} INFO - Starting attempt 1 of 1
[2025-01-02T01:50:03.808+0000] {taskinstance.py:2889} INFO - Executing <Task(PythonOperator): daily_news_etl_run> on 2025-01-02 01:40:00+00:00
[2025-01-02T01:50:03.819+0000] {warnings.py:112} WARNING - /home/***/.local/lib/python3.12/site-packages/***/task/task_runner/standard_task_runner.py:70: DeprecationWarning: This process (pid=712) is multi-threaded, use of fork() may lead to deadlocks in the child.
  pid = os.fork()

[2025-01-02T01:50:03.820+0000] {standard_task_runner.py:72} INFO - Started process 714 to run task
[2025-01-02T01:50:03.821+0000] {standard_task_runner.py:104} INFO - Running: ['***', 'tasks', 'run', 'daily_news_dag', 'daily_news_etl_run', 'scheduled__2025-01-02T01:40:00+00:00', '--job-id', '53', '--raw', '--subdir', 'DAGS_FOLDER/daily_news_dag.py', '--cfg-path', '/tmp/tmpswdyarl7']
[2025-01-02T01:50:03.824+0000] {standard_task_runner.py:105} INFO - Job 53: Subtask daily_news_etl_run
[2025-01-02T01:50:03.840+0000] {warnings.py:112} WARNING - /home/***/.local/lib/python3.12/site-packages/***/settings.py:209: DeprecationWarning: The sql_alchemy_conn option in [core] has been moved to the sql_alchemy_conn option in [database] - the old setting has been used, but please update your config.
  SQL_ALCHEMY_CONN = conf.get("database", "SQL_ALCHEMY_CONN")

[2025-01-02T01:50:03.886+0000] {task_command.py:467} INFO - Running <TaskInstance: daily_news_dag.daily_news_etl_run scheduled__2025-01-02T01:40:00+00:00 [running]> on host a381afd707a7
[2025-01-02T01:50:03.886+0000] {warnings.py:112} WARNING - /home/***/.local/lib/python3.12/site-packages/***/settings.py:470: DeprecationWarning: The sql_alchemy_conn option in [core] has been moved to the sql_alchemy_conn option in [database] - the old setting has been used, but please update your config.
  if conf.get("database", "sql_alchemy_conn") == "none://":

[2025-01-02T01:50:03.988+0000] {taskinstance.py:3132} INFO - Exporting env vars: AIRFLOW_CTX_DAG_OWNER='***' AIRFLOW_CTX_DAG_ID='daily_news_dag' AIRFLOW_CTX_TASK_ID='daily_news_etl_run' AIRFLOW_CTX_EXECUTION_DATE='2025-01-02T01:40:00+00:00' AIRFLOW_CTX_TRY_NUMBER='1' AIRFLOW_CTX_DAG_RUN_ID='scheduled__2025-01-02T01:40:00+00:00'
[2025-01-02T01:50:03.989+0000] {taskinstance.py:731} INFO - ::endgroup::
[2025-01-02T01:50:04.005+0000] {daily_news_etl.py:21} ERROR - API_KEY not found in environment variables.
[2025-01-02T01:50:04.005+0000] {daily_news_etl.py:23} ERROR - DB_CONNECTION not found in environment variables.
[2025-01-02T01:50:04.005+0000] {daily_news_etl.py:130} INFO - Starting ETL process
[2025-01-02T01:50:04.006+0000] {daily_news_etl.py:30} INFO - Fetching news for business category
[2025-01-02T01:50:04.376+0000] {daily_news_etl.py:37} ERROR - Fetching news for business category failed: {'status': 'error', 'results': {'message': 'The API Key is missing. Please sign up to receive your free API key at: https://newsdata.io/register', 'code': 'Unauthorized'}}
[2025-01-02T01:50:04.377+0000] {taskinstance.py:3313} ERROR - Task failed due to SystemExit(1)
[2025-01-02T01:50:04.389+0000] {taskinstance.py:1225} INFO - Marking task as FAILED. dag_id=daily_news_dag, task_id=daily_news_etl_run, run_id=scheduled__2025-01-02T01:40:00+00:00, execution_date=20250102T014000, start_date=20250102T015003, end_date=20250102T015004
[2025-01-02T01:50:04.404+0000] {taskinstance.py:340} INFO - ::group::Post task execution logs
[2025-01-02T01:50:04.405+0000] {standard_task_runner.py:124} ERROR - Failed to execute job 53 for task daily_news_etl_run (Task failed due to SystemExit(1); 714)
Traceback (most recent call last):
  File "/opt/airflow/dags/scripts/daily_news_etl.py", line 31, in get_api
    response = api.latest_api(q=category, language='en', image=False, video=False, scroll=True, max_result=30)
               ^^^^^^^^^^^^^^^^^^^^^^^^^^^^^^^^^^^^^^^^^^^^^^^^^^^^^^^^^^^^^^^^^^^^^^^^^^^^^^^^^^^^^^^^^^^^^^^
  File "/home/airflow/.local/lib/python3.12/site-packages/newsdataapi/newsdataapi_client.py", line 238, in latest_api
    return self.__get_feeds_all(url=f'{self.latest_url}?{URL_parameters_encoded}',max_result=max_result)
           ^^^^^^^^^^^^^^^^^^^^^^^^^^^^^^^^^^^^^^^^^^^^^^^^^^^^^^^^^^^^^^^^^^^^^^^^^^^^^^^^^^^^^^^^^^^^^
  File "/home/airflow/.local/lib/python3.12/site-packages/newsdataapi/newsdataapi_client.py", line 179, in __get_feeds_all
    raise e
  File "/home/airflow/.local/lib/python3.12/site-packages/newsdataapi/newsdataapi_client.py", line 176, in __get_feeds_all
    response = self.__get_feeds(url=f'{url}&page={data.get("nextPage")}' if data.get('results') else url)
               ^^^^^^^^^^^^^^^^^^^^^^^^^^^^^^^^^^^^^^^^^^^^^^^^^^^^^^^^^^^^^^^^^^^^^^^^^^^^^^^^^^^^^^^^^^
  File "/home/airflow/.local/lib/python3.12/site-packages/newsdataapi/newsdataapi_client.py", line 145, in __get_feeds
    raise NewsdataException(response.json())
newsdataapi.newsdataapi_exception.NewsdataException: {'status': 'error', 'results': {'message': 'The API Key is missing. Please sign up to receive your free API key at: https://newsdata.io/register', 'code': 'Unauthorized'}}

During handling of the above exception, another exception occurred:

Traceback (most recent call last):
  File "/home/airflow/.local/lib/python3.12/site-packages/airflow/models/taskinstance.py", line 273, in _run_raw_task
    TaskInstance._execute_task_with_callbacks(
  File "/home/airflow/.local/lib/python3.12/site-packages/airflow/models/taskinstance.py", line 3159, in _execute_task_with_callbacks
    result = self._execute_task(context, task_orig)
             ^^^^^^^^^^^^^^^^^^^^^^^^^^^^^^^^^^^^^^
  File "/home/airflow/.local/lib/python3.12/site-packages/airflow/models/taskinstance.py", line 3183, in _execute_task
    return _execute_task(self, context, task_orig)
           ^^^^^^^^^^^^^^^^^^^^^^^^^^^^^^^^^^^^^^^
  File "/home/airflow/.local/lib/python3.12/site-packages/airflow/models/taskinstance.py", line 767, in _execute_task
    result = _execute_callable(context=context, **execute_callable_kwargs)
             ^^^^^^^^^^^^^^^^^^^^^^^^^^^^^^^^^^^^^^^^^^^^^^^^^^^^^^^^^^^^^
  File "/home/airflow/.local/lib/python3.12/site-packages/airflow/models/taskinstance.py", line 733, in _execute_callable
    return ExecutionCallableRunner(
           ^^^^^^^^^^^^^^^^^^^^^^^^
  File "/home/airflow/.local/lib/python3.12/site-packages/airflow/utils/operator_helpers.py", line 252, in run
    return self.func(*args, **kwargs)
           ^^^^^^^^^^^^^^^^^^^^^^^^^^
  File "/home/airflow/.local/lib/python3.12/site-packages/airflow/models/baseoperator.py", line 422, in wrapper
    return func(self, *args, **kwargs)
           ^^^^^^^^^^^^^^^^^^^^^^^^^^^
  File "/home/airflow/.local/lib/python3.12/site-packages/airflow/operators/python.py", line 238, in execute
    return_value = self.execute_callable()
                   ^^^^^^^^^^^^^^^^^^^^^^^
  File "/home/airflow/.local/lib/python3.12/site-packages/airflow/operators/python.py", line 256, in execute_callable
    return runner.run(*self.op_args, **self.op_kwargs)
           ^^^^^^^^^^^^^^^^^^^^^^^^^^^^^^^^^^^^^^^^^^^
  File "/home/airflow/.local/lib/python3.12/site-packages/airflow/utils/operator_helpers.py", line 252, in run
    return self.func(*args, **kwargs)
           ^^^^^^^^^^^^^^^^^^^^^^^^^^
  File "/opt/airflow/dags/scripts/daily_news_etl.py", line 132, in main
    response = etl.get_api(category)
               ^^^^^^^^^^^^^^^^^^^^^
  File "/opt/airflow/dags/scripts/daily_news_etl.py", line 38, in get_api
    exit(1)
  File "<frozen _sitebuiltins>", line 26, in __call__
SystemExit: 1

During handling of the above exception, another exception occurred:

Traceback (most recent call last):
  File "/home/airflow/.local/lib/python3.12/site-packages/airflow/task/task_runner/standard_task_runner.py", line 117, in _start_by_fork
    ret = args.func(args, dag=self.dag)
          ^^^^^^^^^^^^^^^^^^^^^^^^^^^^^
  File "/home/airflow/.local/lib/python3.12/site-packages/airflow/cli/cli_config.py", line 49, in command
    return func(*args, **kwargs)
           ^^^^^^^^^^^^^^^^^^^^^
  File "/home/airflow/.local/lib/python3.12/site-packages/airflow/utils/cli.py", line 116, in wrapper
    return f(*args, **kwargs)
           ^^^^^^^^^^^^^^^^^^
  File "/home/airflow/.local/lib/python3.12/site-packages/airflow/cli/commands/task_command.py", line 483, in task_run
    task_return_code = _run_task_by_selected_method(args, _dag, ti)
                       ^^^^^^^^^^^^^^^^^^^^^^^^^^^^^^^^^^^^^^^^^^^^
  File "/home/airflow/.local/lib/python3.12/site-packages/airflow/cli/commands/task_command.py", line 256, in _run_task_by_selected_method
    return _run_raw_task(args, ti)
           ^^^^^^^^^^^^^^^^^^^^^^^
  File "/home/airflow/.local/lib/python3.12/site-packages/airflow/cli/commands/task_command.py", line 341, in _run_raw_task
    return ti._run_raw_task(
           ^^^^^^^^^^^^^^^^^
  File "/home/airflow/.local/lib/python3.12/site-packages/airflow/utils/session.py", line 97, in wrapper
    return func(*args, session=session, **kwargs)
           ^^^^^^^^^^^^^^^^^^^^^^^^^^^^^^^^^^^^^^
  File "/home/airflow/.local/lib/python3.12/site-packages/airflow/models/taskinstance.py", line 3005, in _run_raw_task
    return _run_raw_task(
           ^^^^^^^^^^^^^^
  File "/home/airflow/.local/lib/python3.12/site-packages/airflow/models/taskinstance.py", line 334, in _run_raw_task
    raise AirflowException(msg)
airflow.exceptions.AirflowException: Task failed due to SystemExit(1)
[2025-01-02T01:50:04.440+0000] {local_task_job_runner.py:266} INFO - Task exited with return code 1
[2025-01-02T01:50:04.462+0000] {taskinstance.py:3895} INFO - 0 downstream tasks scheduled from follow-on schedule check
[2025-01-02T01:50:04.465+0000] {local_task_job_runner.py:245} INFO - ::endgroup::
